Workbook

Sheet dane_import
A1: Data | B1: mWIG40 | C1: MBK | D1: PGE | E1: FIO_3366.N | F1: DT z kalendarza
A2: 44119 | B2: 3512.7 | C2: 151.5 | D2: 5.314 | E2: 201.33 | F2: =WEEKDAY(A2,2) -> 4
A3: 44120 | B3: 3561.88 | C3: 148.4 | D3: 5.352 | E3: 201.32 | F3: =WEEKDAY(A3,2) -> 5
A4: 44123 | B4: 3564.25 | C4: 149.7 | D4: 5.746 | E4: 201.27 | F4: =WEEKDAY(A4,2) -> 1
A5: 44124 | B5: 3598.66 | C5: 153.2 | D5: 5.664 | E5: 201.43 | F5: =WEEKDAY(A5,2) -> 2
A6: 44125 | B6: 3550.18 | C6: 146.7 | D6: 5.496 | E6: 201.48 | F6: =WEEKDAY(A6,2) -> 3
A7: 44126 | B7: 3540.64 | C7: 148.5 | D7: 5.458 | E7: 201.62 | F7: =WEEKDAY(A7,2) -> 4
A8: 44127 | B8: 3500.81 | C8: 148.3 | D8: 5.272 | E8: 201.64 | F8: =WEEKDAY(A8,2) -> 5
A9: 44130 | B9: 3456.48 | C9: 151.2 | D9: 5.418 | E9: 201.64 | F9: =WEEKDAY(A9,2) -> 1
A10: 44131 | B10: 3435.51 | C10: 140 | D10: 5.106 | E10: 201.76 | F10: =WEEKDAY(A10,2) -> 2
A11: 44132 | B11: 3260.51 | C11: 126.1 | D11: 4.732 | E11: 201.85 | F11: =WEEKDAY(A11,2) -> 3
A12: 44133 | B12: 3262.96 | C12: 120 | D12: 4.496 | E12: 201.92 | F12: =WEEKDAY(A12,2) -> 4
A13: 44134 | B13: 3196.84 | C13: 115.5 | D13: 4.51 | E13: 201.9 | F13: =WEEKDAY(A13,2) -> 5
... A1305: 45944 | B1305: 7725.4 | C1305: 916.4 | D1305: 10.085 | E1305: 265.8 | F1305: =WEEKDAY(A1305,2) -> 2

Sheet dane_gretl
A1: Data | B1: mWIG40 | C1: MBK | D1: PGE | E1: FIO_3366.N
A2: 44119 | B2: 3512.7 | C2: 151.5 | D2: 5.314 | E2: 201.33
A3: 44120 | B3: 3561.88 | C3: 148.4 | D3: 5.352 | E3: 201.32
A4: 44123 | B4: 3564.25 | C4: 149.7 | D4: 5.746 | E4: 201.27
A5: 44124 | B5: 3598.66 | C5: 153.2 | D5: 5.664 | E5: 201.43
A6: 44125 | B6: 3550.18 | C6: 146.7 | D6: 5.496 | E6: 201.48
A7: 44126 | B7: 3540.64 | C7: 148.5 | D7: 5.458 | E7: 201.62
A8: 44127 | B8: 3500.81 | C8: 148.3 | D8: 5.272 | E8: 201.64
A9: 44130 | B9: 3456.48 | C9: 151.2 | D9: 5.418 | E9: 201.64
A10: 44131 | B10: 3435.51 | C10: 140 | D10: 5.106 | E10: 201.76
A11: 44132 | B11: 3260.51 | C11: 126.1 | D11: 4.732 | E11: 201.85
A12: 44133 | B12: 3262.96 | C12: 120 | D12: 4.496 | E12: 201.92
A13: 44134 | B13: 3196.84 | C13: 115.5 | D13: 4.51 | E13: 201.9
... A1305: 45944 | B1305: 7725.4 | C1305: 916.4 | D1305: 10.085 | E1305: 265.8

Sheet stylizowane
A1: Data | B1: lrmWIG40 | C1: lrMBK | D1: lrPGE | E1: lrFIO | G1: Analiza rozkładu
A2: 44120 | B2: =LN(dane_import!B3/dane_import!B2) -> 0.013903523 | C2: =LN(dane_import!C3/dane_import!C2) -> -0.020674294 | D2: =LN(dane_import!D3/dane_import!D2) -> 0.0071254755 | E2: =LN(dane_import!E3/dane_import!E2) -> -4.967093e-05 | H2: lrmWIG40 | I2: lrMBK | J2: lrPGE | K2: lrFIO
A3: 44123 | B3: =LN(dane_import!B4/dane_import!B3) -> 0.00066515769 | C3: =LN(dane_import!C4/dane_import!C3) -> 0.0087219607 | D3: =LN(dane_import!D4/dane_import!D3) -> 0.071033638 | E3: =LN(dane_import!E4/dane_import!E3) -> -0.00024839167 | G3: Min | H3: =MIN(B$2:B$1304) -> -0.12494489 | I3: =MIN(C$2:C$1304) -> -0.15737529 | J3: =MIN(D$2:D$1304) -> -0.11174633 | K3: =MIN(E$2:E$1304) -> -0.0046394536
A4: 44124 | B4: =LN(dane_import!B5/dane_import!B4) -> 0.0096079009 | C4: =LN(dane_import!C5/dane_import!C4) -> 0.023110966 | D4: =LN(dane_import!D5/dane_import!D4) -> -0.014373604 | E4: =LN(dane_import!E5/dane_import!E4) -> 0.00079463625 | G4: Średnia | H4: =AVERAGE(B$2:B$1304) -> 0.00060485697 | I4: =AVERAGE(C$2:C$1304) -> 0.0013813257 | J4: =AVERAGE(D$2:D$1304) -> 0.00049171475 | K4: =AVERAGE(E$2:E$1304) -> 0.00021319938
A5: 44125 | B5: =LN(dane_import!B6/dane_import!B5) -> -0.013563248 | C5: =LN(dane_import!C6/dane_import!C5) -> -0.043354572 | D5: =LN(dane_import!D6/dane_import!D5) -> -0.030109801 | E5: =LN(dane_import!E6/dane_import!E5) -> 0.00024819439 | G5: Max | H5: =MAX(B$2:B$1304) -> 0.071558917 | I5: =MAX(C$2:C$1304) -> 0.21584129 | J5: =MAX(D$2:D$1304) -> 0.14560095 | K5: =MAX(E$2:E$1304) -> 0.015376868
A6: 44126 | B6: =LN(dane_import!B7/dane_import!B6) -> -0.0026908047 | C6: =LN(dane_import!C7/dane_import!C6) -> 0.012195273 | D6: =LN(dane_import!D7/dane_import!D6) -> -0.0069381326 | E6: =LN(dane_import!E7/dane_import!E6) -> 0.00069461675 | G6: Wariancja | H6: =VARA(B$2:B$1304) -> 0.00013913528 | I6: =VARA(C$2:C$1304) -> 0.00077928868 | J6: =VARA(D$2:D$1304) -> 0.00068191348 | K6: =VARA(E$2:E$1304) -> 9.5014548e-07
A7: 44127 | B7: =LN(dane_import!B8/dane_import!B7) -> -0.011313131 | C7: =LN(dane_import!C8/dane_import!C7) -> -0.0013477091 | D7: =LN(dane_import!D8/dane_import!D7) -> -0.034672625 | E7: =LN(dane_import!E8/dane_import!E7) -> 9.9191589e-05 | G7: Ryzyko (SD) | H7: =_xlfn.STDEV.S(B$2:B$1304) -> 0.011795562 | I7: =_xlfn.STDEV.S(C$2:C$1304) -> 0.027915743 | J7: =_xlfn.STDEV.S(D$2:D$1304) -> 0.026113473 | K7: =_xlfn.STDEV.S(E$2:E$1304) -> 0.00097475406
A8: 44130 | B8: =LN(dane_import!B9/dane_import!B8) -> -0.01274364 | C8: =LN(dane_import!C9/dane_import!C8) -> 0.019366215 | D8: =LN(dane_import!D9/dane_import!D8) -> 0.027316946 | E8: =LN(dane_import!E9/dane_import!E8) -> 0 | G8: Asymetria | H8: =SKEW(B$2:B$1304) -> -0.94514513 | I8: =SKEW(C$2:C$1304) -> 0.37899678 | J8: =SKEW(D$2:D$1304) -> 0.4744813 | K8: =SKEW(E$2:E$1304) -> 2.7812165
A9: 44131 | B9: =LN(dane_import!B10/dane_import!B9) -> -0.0060853439 | C9: =LN(dane_import!C10/dane_import!C9) -> -0.076961041 | D9: =LN(dane_import!D10/dane_import!D9) -> -0.059310425 | E9: =LN(dane_import!E10/dane_import!E9) -> 0.000594943 | G9: S(A) - błąd skośności | H9: =SQRT(6/H15) -> 0.067858369 | I9: =SQRT(6/I15) -> 0.067858369 | J9: =SQRT(6/J15) -> 0.067858369 | K9: =SQRT(6/K15) -> 0.067858369
A10: 44132 | B10: =LN(dane_import!B11/dane_import!B10) -> -0.052281761 | C10: =LN(dane_import!C11/dane_import!C10) -> -0.10456718 | D10: =LN(dane_import!D11/dane_import!D10) -> -0.076068373 | E10: =LN(dane_import!E11/dane_import!E10) -> 0.00044597508 | G10: Z | H10: =H8/H9 -> -13.928203 | I10: =I8/I9 -> 5.5851148 | J10: =J8/J9 -> 6.9922297 | K10: =K8/K9 -> 40.985607 | L10: |Z| > 1,96 | N10: Z = A/ S(A)
A11: 44133 | B11: =LN(dane_import!B12/dane_import!B11) -> 0.00075113402 | C11: =LN(dane_import!C12/dane_import!C11) -> -0.0495835 | D11: =LN(dane_import!D12/dane_import!D11) -> -0.051159834 | E11: =LN(dane_import!E12/dane_import!E11) -> 0.00034673205 | G11: Spłaszcenie / Kurtoza | H11: =KURT(B$2:B$1304) -> 11.755532 | I11: =KURT(C$2:C$1304) -> 4.7592264 | J11: =KURT(D$2:D$1304) -> 3.5581472 | K11: =KURT(E$2:E$1304) -> 48.00142
A12: 44134 | B12: =LN(dane_import!B13/dane_import!B12) -> -0.020471937 | C12: =LN(dane_import!C13/dane_import!C12) -> -0.038221213 | D12: =LN(dane_import!D13/dane_import!D12) -> 0.0031090409 | E12: =LN(dane_import!E13/dane_import!E12) -> -9.9054034e-05 | G12: S(KR) - błąd kurtozy | H12: =SQRT(24/H15) -> 0.13571674 | I12: =SQRT(24/I15) -> 0.13571674 | J12: =SQRT(24/J15) -> 0.13571674 | K12: =SQRT(24/K15) -> 0.13571674
A13: 44137 | B13: =LN(dane_import!B14/dane_import!B13) -> 0.017104295 | C13: =LN(dane_import!C14/dane_import!C13) -> 0.009478744 | D13: =LN(dane_import!D14/dane_import!D13) -> 0.034861918 | E13: =LN(dane_import!E14/dane_import!E13) -> 0 | G13: Z | H13: =(H11-3)/H12 -> 64.513278 | I13: =(I11-3)/I12 -> 12.962486 | J13: =(J11-3)/J12 -> 4.112589 | K13: =(K11-3)/K12 -> 331.58342 | L13: |Z| > 1,96 | N13: Z = KR / S(KR)
A14: 44138 | B14: =LN(dane_import!B15/dane_import!B14) -> 0.032959531 | C14: =LN(dane_import!C15/dane_import!C14) -> 0.12405265 | D14: =LN(dane_import!D15/dane_import!D14) -> 0.084545813 | E14: =LN(dane_import!E15/dane_import!E14) -> 0.00084164671 | G14: statystyka JB | H14: =H15*((H8^2)/6+(H11^2)/24) -> 7696.6972 | I14: =I15*((I8^2)/6+(I11^2)/24) -> 1260.9126 | J14: =J15*((J8^2)/6+(J11^2)/24) -> 736.2461 | K14: =K15*((K8^2)/6+(K11^2)/24) -> 126775.22 | L14: chi^2 | M14: =_xlfn.CHISQ.INV.RT(0.05,2) -> 5.9914645
A15: 44139 | B15: =LN(dane_import!B16/dane_import!B15) -> 0.0042842258 | C15: =LN(dane_import!C16/dane_import!C15) -> -0.050496164 | D15: =LN(dane_import!D16/dane_import!D15) -> 0.014844023 | E15: =LN(dane_import!E16/dane_import!E15) -> 0.00014845238 | G15: T | H15: =COUNT(B:B) -> 1303 | I15: =COUNT(C:C) -> 1303 | J15: =COUNT(D:D) -> 1303 | K15: =COUNT(E:E) -> 1303
A16: 44140 | B16: =LN(dane_import!B17/dane_import!B16) -> 0.033385132 | C16: =LN(dane_import!C17/dane_import!C16) -> -0.0031923411 | D16: =LN(dane_import!D17/dane_import!D16) -> 0.016535658 | E16: =LN(dane_import!E17/dane_import!E16) -> 0.0011868264
A17: 44141 | B17: =LN(dane_import!B18/dane_import!B17) -> 0.0064291821 | C17: =LN(dane_import!C18/dane_import!C17) -> -0.011254138 | D17: =LN(dane_import!D18/dane_import!D17) -> -0.022758938 | E17: =LN(dane_import!E18/dane_import!E17) -> 0.00098794713
A18: 44144 | B18: =LN(dane_import!B19/dane_import!B18) -> 0.031109702 | C18: =LN(dane_import!C19/dane_import!C18) -> 0.21584129 | D18: =LN(dane_import!D19/dane_import!D18) -> 0.14164316 | E18: =LN(dane_import!E19/dane_import!E18) -> 0.00088831867 | G18: Korelacje
A19: 44145 | B19: =LN(dane_import!B20/dane_import!B19) -> 0.013037387 | C19: =LN(dane_import!C20/dane_import!C19) -> 0.096198148 | D19: =LN(dane_import!D20/dane_import!D19) -> -0.0010164324 | E19: =LN(dane_import!E20/dane_import!E19) -> -4.9330341e-05 | H19: lrmWIG40 | I19: lrMBK | J19: lrPGE | K19: lrFIO
A20: 44146 | B20: =LN(dane_import!B21/dane_import!B20) -> 0 | C20: =LN(dane_import!C21/dane_import!C20) -> 0 | D20: =LN(dane_import!D21/dane_import!D20) -> 0 | E20: =LN(dane_import!E21/dane_import!E20) -> 0 | G20: lrmWIG40 | H20: =CORREL(B$2:B$1304,$B$2:$B$1304) -> 1 | I20: =CORREL(C$2:C$1304,$B$2:$B$1304) -> 0.67236904 | J20: =CORREL(D$2:D$1304,$B$2:$B$1304) -> 0.47911266 | K20: =CORREL(E$2:E$1304,$B$2:$B$1304) -> 0.13316663
A21: 44147 | B21: =LN(dane_import!B22/dane_import!B21) -> 0.0045984715 | C21: =LN(dane_import!C22/dane_import!C21) -> 0.0011827322 | D21: =LN(dane_import!D22/dane_import!D21) -> 0.02179466 | E21: =LN(dane_import!E22/dane_import!E21) -> -0.00014800562 | G21: lrMBK | H21: =CORREL(B$2:B$1304,$C$2:$C$1304) -> 0.67236904 | I21: =CORREL(C$2:C$1304,$C$2:$C$1304) -> 1 | J21: =CORREL(D$2:D$1304,$C$2:$C$1304) -> 0.31201895 | K21: =CORREL(E$2:E$1304,$C$2:$C$1304) -> 0.077929255
A22: 44148 | B22: =LN(dane_import!B23/dane_import!B22) -> -0.013150255 | C22: =LN(dane_import!C23/dane_import!C22) -> -0.051542174 | D22: =LN(dane_import!D23/dane_import!D22) -> 0.009901071 | E22: =LN(dane_import!E23/dane_import!E22) -> 0.00049326692 | G22: lrPGE | H22: =CORREL(B$2:B$1304,$D$2:$D$1304) -> 0.47911266 | I22: =CORREL(C$2:C$1304,$D$2:$D$1304) -> 0.31201895 | J22: =CORREL(D$2:D$1304,$D$2:$D$1304) -> 1 | K22: =CORREL(E$2:E$1304,$D$2:$D$1304) -> -0.0235938
A23: 44151 | B23: =LN(dane_import!B24/dane_import!B23) -> 0.019472505 | C23: =LN(dane_import!C24/dane_import!C23) -> 0.059196024 | D23: =LN(dane_import!D24/dane_import!D23) -> -0.0065898097 | E23: =LN(dane_import!E24/dane_import!E23) -> 4.9313312e-05 | G23: lrFIO | H23: =CORREL(B$2:B$1304,$E$2:$E$1304) -> 0.13316663 | I23: =CORREL(C$2:C$1304,$E$2:$E$1304) -> 0.077929255 | J23: =CORREL(D$2:D$1304,$E$2:$E$1304) -> -0.0235938 | K23: =CORREL(E$2:E$1304,$E$2:$E$1304) -> 1
A24: 44152 | B24: =LN(dane_import!B25/dane_import!B24) -> -0.0035494866 | C24: =LN(dane_import!C25/dane_import!C24) -> -0.0029368597 | D24: =LN(dane_import!D25/dane_import!D24) -> -0.0099668599 | E24: =LN(dane_import!E25/dane_import!E24) -> -9.8629056e-05
A25: 44153 | B25: =LN(dane_import!B26/dane_import!B25) -> 0.0073629286 | C25: =LN(dane_import!C26/dane_import!C25) -> -0.019002947 | D25: =LN(dane_import!D26/dane_import!D25) -> 0.017213268 | E25: =LN(dane_import!E26/dane_import!E25) -> 0.00078876021
A26: 44154 | B26: =LN(dane_import!B27/dane_import!B26) -> -0.013680518 | C26: =LN(dane_import!C27/dane_import!C26) -> 0.0011983225 | D26: =LN(dane_import!D27/dane_import!D26) -> -0.013879932 | E26: =LN(dane_import!E27/dane_import!E26) -> -9.8561009e-05
A27: 44155 | B27: =LN(dane_import!B28/dane_import!B27) -> 0.0034933062 | C27: =LN(dane_import!C28/dane_import!C27) -> -0.026700615 | D27: =LN(dane_import!D28/dane_import!D27) -> 0.0092746607 | E27: =LN(dane_import!E28/dane_import!E27) -> -0.00014785973
A28: 44158 | B28: =LN(dane_import!B29/dane_import!B28) -> 0.010254314 | C28: =LN(dane_import!C29/dane_import!C28) -> 0.032075367 | D28: =LN(dane_import!D29/dane_import!D28) -> 0.010169023 | E28: =LN(dane_import!E29/dane_import!E28) -> -9.8585301e-05
A29: 44159 | B29: =LN(dane_import!B30/dane_import!B29) -> -0.0010795541 | C29: =LN(dane_import!C30/dane_import!C29) -> 0.010074159 | D29: =LN(dane_import!D30/dane_import!D29) -> -0.0081927379 | E29: =LN(dane_import!E30/dane_import!E29) -> 0.00019716088
A30: 44160 | B30: =LN(dane_import!B31/dane_import!B30) -> 0.008244286 | C30: =LN(dane_import!C31/dane_import!C30) -> -0.0047281412 | D30: =LN(dane_import!D31/dane_import!D30) -> 0.0036130767 | E30: =LN(dane_import!E31/dane_import!E30) -> -0.00069023323
A31: 44161 | B31: =LN(dane_import!B32/dane_import!B31) -> 0.0011026387 | C31: =LN(dane_import!C32/dane_import!C31) -> -0.0155227 | D31: =LN(dane_import!D32/dane_import!D31) -> 0 | E31: =LN(dane_import!E32/dane_import!E31) -> -4.9320609e-05
A32: 44162 | B32: =LN(dane_import!B33/dane_import!B32) -> 0.0034200241 | C32: =LN(dane_import!C33/dane_import!C32) -> -0.056946077 | D32: =LN(dane_import!D33/dane_import!D32) -> 0 | E32: =LN(dane_import!E33/dane_import!E32) -> 0.00029588717
A33: 44165 | B33: =LN(dane_import!B34/dane_import!B33) -> -0.010895925 | C33: =LN(dane_import!C34/dane_import!C33) -> -0.036320464 | D33: =LN(dane_import!D34/dane_import!D33) -> -0.056657093 | E33: =LN(dane_import!E34/dane_import!E33) -> 0.00019720949
A34: 44166 | B34: =LN(dane_import!B35/dane_import!B34) -> -0.016197652 | C34: =LN(dane_import!C35/dane_import!C34) -> 0.017027261 | D34: =LN(dane_import!D35/dane_import!D34) -> -0.015384919 | E34: =LN(dane_import!E35/dane_import!E34) -> 4.9296295e-05
A35: 44167 | B35: =LN(dane_import!B36/dane_import!B35) -> 0.010614501 | C35: =LN(dane_import!C36/dane_import!C35) -> 0.0038885337 | D35: =LN(dane_import!D36/dane_import!D35) -> -0.013480162 | E35: =LN(dane_import!E36/dane_import!E35) -> -0.00029581423
... A1304: 45944 | B1304: =LN(dane_import!B1305/dane_import!B1304) -> -0.011083405 | C1304: =LN(dane_import!C1305/dane_import!C1304) -> -0.0093407869 | D1304: =LN(dane_import!D1305/dane_import!D1304) -> -0.056855388 | E1304: =LN(dane_import!E1305/dane_import!E1304) -> 0.00022575912

Sheet Wykresy mWIG40
A1: Data | B1: mWIG40 | C1: lrmWIG40 | D1: |lrmWIG41| | E1: lrmWIG40^2 | H1: Ceny i zwroty mWIG40
A2: 44120 | B2: 3561.88 | C2: =LN(dane_import!B3/dane_import!B2) -> 0.013903523 | D2: =ABS(C2) -> 0.013903523 | E2: =C2^2 -> 0.00019330795
A3: 44123 | B3: 3564.25 | C3: =LN(dane_import!B4/dane_import!B3) -> 0.00066515769 | D3: =ABS(C3) -> 0.00066515769 | E3: =C3^2 -> 4.4243475e-07
A4: 44124 | B4: 3598.66 | C4: =LN(dane_import!B5/dane_import!B4) -> 0.0096079009 | D4: =ABS(C4) -> 0.0096079009 | E4: =C4^2 -> 9.231176e-05
A5: 44125 | B5: 3550.18 | C5: =LN(dane_import!B6/dane_import!B5) -> -0.013563248 | D5: =ABS(C5) -> 0.013563248 | E5: =C5^2 -> 0.00018396168
A6: 44126 | B6: 3540.64 | C6: =LN(dane_import!B7/dane_import!B6) -> -0.0026908047 | D6: =ABS(C6) -> 0.0026908047 | E6: =C6^2 -> 7.2404297e-06
A7: 44127 | B7: 3500.81 | C7: =LN(dane_import!B8/dane_import!B7) -> -0.011313131 | D7: =ABS(C7) -> 0.011313131 | E7: =C7^2 -> 0.00012798694
A8: 44130 | B8: 3456.48 | C8: =LN(dane_import!B9/dane_import!B8) -> -0.01274364 | D8: =ABS(C8) -> 0.01274364 | E8: =C8^2 -> 0.00016240036
A9: 44131 | B9: 3435.51 | C9: =LN(dane_import!B10/dane_import!B9) -> -0.0060853439 | D9: =ABS(C9) -> 0.0060853439 | E9: =C9^2 -> 3.7031411e-05
A10: 44132 | B10: 3260.51 | C10: =LN(dane_import!B11/dane_import!B10) -> -0.052281761 | D10: =ABS(C10) -> 0.052281761 | E10: =C10^2 -> 0.0027333826
A11: 44133 | B11: 3262.96 | C11: =LN(dane_import!B12/dane_import!B11) -> 0.00075113402 | D11: =ABS(C11) -> 0.00075113402 | E11: =C11^2 -> 5.6420231e-07
A12: 44134 | B12: 3196.84 | C12: =LN(dane_import!B13/dane_import!B12) -> -0.020471937 | D12: =ABS(C12) -> 0.020471937 | E12: =C12^2 -> 0.0004191002
A13: 44137 | B13: 3251.99 | C13: =LN(dane_import!B14/dane_import!B13) -> 0.017104295 | D13: =ABS(C13) -> 0.017104295 | E13: =C13^2 -> 0.0002925569
... A1304: 45944 | B1304: 7725.4 | C1304: =LN(dane_import!B1305/dane_import!B1304) -> -0.011083405 | D1304: =ABS(C1304) -> 0.011083405 | E1304: =C1304^2 -> 0.00012284188

Sheet Wykresy MBK
A1: Data | B1: MBK | C1: lrMBK | D1: |lrMBK| | E1: lrMBK^2 | H1: Ceny i zwroty MBK
A2: 44120 | B2: 148.4 | C2: =LN(dane_import!C3/dane_import!C2) -> -0.020674294 | D2: =ABS(C2) -> 0.020674294 | E2: =C2^2 -> 0.00042742644
A3: 44123 | B3: 149.7 | C3: =LN(dane_import!C4/dane_import!C3) -> 0.0087219607 | D3: =ABS(C3) -> 0.0087219607 | E3: =C3^2 -> 7.6072598e-05
A4: 44124 | B4: 153.2 | C4: =LN(dane_import!C5/dane_import!C4) -> 0.023110966 | D4: =ABS(C4) -> 0.023110966 | E4: =C4^2 -> 0.00053411674
A5: 44125 | B5: 146.7 | C5: =LN(dane_import!C6/dane_import!C5) -> -0.043354572 | D5: =ABS(C5) -> 0.043354572 | E5: =C5^2 -> 0.0018796189
A6: 44126 | B6: 148.5 | C6: =LN(dane_import!C7/dane_import!C6) -> 0.012195273 | D6: =ABS(C6) -> 0.012195273 | E6: =C6^2 -> 0.00014872469
A7: 44127 | B7: 148.3 | C7: =LN(dane_import!C8/dane_import!C7) -> -0.0013477091 | D7: =ABS(C7) -> 0.0013477091 | E7: =C7^2 -> 1.8163198e-06
A8: 44130 | B8: 151.2 | C8: =LN(dane_import!C9/dane_import!C8) -> 0.019366215 | D8: =ABS(C8) -> 0.019366215 | E8: =C8^2 -> 0.00037505027
A9: 44131 | B9: 140 | C9: =LN(dane_import!C10/dane_import!C9) -> -0.076961041 | D9: =ABS(C9) -> 0.076961041 | E9: =C9^2 -> 0.0059230019
A10: 44132 | B10: 126.1 | C10: =LN(dane_import!C11/dane_import!C10) -> -0.10456718 | D10: =ABS(C10) -> 0.10456718 | E10: =C10^2 -> 0.010934295
A11: 44133 | B11: 120 | C11: =LN(dane_import!C12/dane_import!C11) -> -0.0495835 | D11: =ABS(C11) -> 0.0495835 | E11: =C11^2 -> 0.0024585235
A12: 44134 | B12: 115.5 | C12: =LN(dane_import!C13/dane_import!C12) -> -0.038221213 | D12: =ABS(C12) -> 0.038221213 | E12: =C12^2 -> 0.0014608611
A13: 44137 | B13: 116.6 | C13: =LN(dane_import!C14/dane_import!C13) -> 0.009478744 | D13: =ABS(C13) -> 0.009478744 | E13: =C13^2 -> 8.9846587e-05
... A1304: 45944 | B1304: 916.4 | C1304: =LN(dane_import!C1305/dane_import!C1304) -> -0.0093407869 | D1304: =ABS(C1304) -> 0.0093407869 | E1304: =C1304^2 -> 8.7250301e-05

Sheet Wykresy PGE 
A1: Data | B1: PGE | C1: lrPGE | D1: |lrPGE| | E1: lrPGE^2 | H1: Ceny i zwroty PGE
A2: 44120 | B2: 5.352 | C2: =LN(dane_import!D3/dane_import!D2) -> 0.0071254755 | D2: =ABS(C2) -> 0.0071254755 | E2: =C2^2 -> 5.0772401e-05
A3: 44123 | B3: 5.746 | C3: =LN(dane_import!D4/dane_import!D3) -> 0.071033638 | D3: =ABS(C3) -> 0.071033638 | E3: =C3^2 -> 0.0050457777
A4: 44124 | B4: 5.664 | C4: =LN(dane_import!D5/dane_import!D4) -> -0.014373604 | D4: =ABS(C4) -> 0.014373604 | E4: =C4^2 -> 0.0002066005
A5: 44125 | B5: 5.496 | C5: =LN(dane_import!D6/dane_import!D5) -> -0.030109801 | D5: =ABS(C5) -> 0.030109801 | E5: =C5^2 -> 0.00090660014
A6: 44126 | B6: 5.458 | C6: =LN(dane_import!D7/dane_import!D6) -> -0.0069381326 | D6: =ABS(C6) -> 0.0069381326 | E6: =C6^2 -> 4.8137684e-05
A7: 44127 | B7: 5.272 | C7: =LN(dane_import!D8/dane_import!D7) -> -0.034672625 | D7: =ABS(C7) -> 0.034672625 | E7: =C7^2 -> 0.0012021909
A8: 44130 | B8: 5.418 | C8: =LN(dane_import!D9/dane_import!D8) -> 0.027316946 | D8: =ABS(C8) -> 0.027316946 | E8: =C8^2 -> 0.00074621556
A9: 44131 | B9: 5.106 | C9: =LN(dane_import!D10/dane_import!D9) -> -0.059310425 | D9: =ABS(C9) -> 0.059310425 | E9: =C9^2 -> 0.0035177265
A10: 44132 | B10: 4.732 | C10: =LN(dane_import!D11/dane_import!D10) -> -0.076068373 | D10: =ABS(C10) -> 0.076068373 | E10: =C10^2 -> 0.0057863973
A11: 44133 | B11: 4.496 | C11: =LN(dane_import!D12/dane_import!D11) -> -0.051159834 | D11: =ABS(C11) -> 0.051159834 | E11: =C11^2 -> 0.0026173286
A12: 44134 | B12: 4.51 | C12: =LN(dane_import!D13/dane_import!D12) -> 0.0031090409 | D12: =ABS(C12) -> 0.0031090409 | E12: =C12^2 -> 9.6661355e-06
A13: 44137 | B13: 4.67 | C13: =LN(dane_import!D14/dane_import!D13) -> 0.034861918 | D13: =ABS(C13) -> 0.034861918 | E13: =C13^2 -> 0.0012153533
... A1304: 45944 | B1304: 10.085 | C1304: =LN(dane_import!D1305/dane_import!D1304) -> -0.056855388 | D1304: =ABS(C1304) -> 0.056855388 | E1304: =C1304^2 -> 0.0032325351

Sheet Wykresy FIO
A1: Data | B1: FIO | C1: lrFIO | D1: |lrFIO| | E1: lrFIO^2
A2: 44120 | B2: 201.32 | C2: =LN(dane_import!E3/dane_import!E2) -> -4.967093e-05 | D2: =ABS(C2) -> 4.967093e-05 | E2: =C2^2 -> 2.4672013e-09
A3: 44123 | B3: 201.27 | C3: =LN(dane_import!E4/dane_import!E3) -> -0.00024839167 | D3: =ABS(C3) -> 0.00024839167 | E3: =C3^2 -> 6.1698419e-08
A4: 44124 | B4: 201.43 | C4: =LN(dane_import!E5/dane_import!E4) -> 0.00079463625 | D4: =ABS(C4) -> 0.00079463625 | E4: =C4^2 -> 6.3144677e-07
A5: 44125 | B5: 201.48 | C5: =LN(dane_import!E6/dane_import!E5) -> 0.00024819439 | D5: =ABS(C5) -> 0.00024819439 | E5: =C5^2 -> 6.1600454e-08
A6: 44126 | B6: 201.62 | C6: =LN(dane_import!E7/dane_import!E6) -> 0.00069461675 | D6: =ABS(C6) -> 0.00069461675 | E6: =C6^2 -> 4.8249243e-07
A7: 44127 | B7: 201.64 | C7: =LN(dane_import!E8/dane_import!E7) -> 9.9191589e-05 | D7: =ABS(C7) -> 9.9191589e-05 | E7: =C7^2 -> 9.8389713e-09
A8: 44130 | B8: 201.64 | C8: =LN(dane_import!E9/dane_import!E8) -> 0 | D8: =ABS(C8) -> 0 | E8: =C8^2 -> 0
A9: 44131 | B9: 201.76 | C9: =LN(dane_import!E10/dane_import!E9) -> 0.000594943 | D9: =ABS(C9) -> 0.000594943 | E9: =C9^2 -> 3.5395718e-07
A10: 44132 | B10: 201.85 | C10: =LN(dane_import!E11/dane_import!E10) -> 0.00044597508 | D10: =ABS(C10) -> 0.00044597508 | E10: =C10^2 -> 1.9889377e-07
A11: 44133 | B11: 201.92 | C11: =LN(dane_import!E12/dane_import!E11) -> 0.00034673205 | D11: =ABS(C11) -> 0.00034673205 | E11: =C11^2 -> 1.2022312e-07
A12: 44134 | B12: 201.9 | C12: =LN(dane_import!E13/dane_import!E12) -> -9.9054034e-05 | D12: =ABS(C12) -> 9.9054034e-05 | E12: =C12^2 -> 9.8117017e-09
A13: 44137 | B13: 201.9 | C13: =LN(dane_import!E14/dane_import!E13) -> 0 | D13: =ABS(C13) -> 0 | E13: =C13^2 -> 0
... A1304: 45944 | B1304: 265.8 | C1304: =LN(dane_import!E1305/dane_import!E1304) -> 0.00022575912 | D1304: =ABS(C1304) -> 0.00022575912 | E1304: =C1304^2 -> 5.0967178e-08

Sheet analiza portfelowa
A1: Data | B1: MBK | C1: lrMBK | D1: PGE | E1: lrPGE | H1: spółka | I1: A MBK | J1: B PGE | M1: rf | N1: 0
A2: 44119 | B2: 151.5 | D2: 5.314 | H2: zwrot (średnia) | I2: =AVERAGE(C3:C1305) -> 0.0013813257 | J2: =AVERAGE(E3:E1305) -> 0.00049171475
A3: 44120 | B3: 148.4 | C3: =LN(B3/B2) -> -0.020674294 | D3: 5.352 | E3: =LN(D3/D2) -> 0.0071254755 | H3: wariancja | I3: =_xlfn.VAR.S(C3:C1305) -> 0.00077928868 | J3: =_xlfn.VAR.S(E3:E1305) -> 0.00068191348
A4: 44123 | B4: 149.7 | C4: =LN(B4/B3) -> 0.0087219607 | D4: 5.746 | E4: =LN(D4/D3) -> 0.071033638 | H4: ryzyko (SD) | I4: =_xlfn.STDEV.S(C3:C1305) -> 0.027915743 | J4: =_xlfn.STDEV.S(E3:E1305) -> 0.026113473
A5: 44124 | B5: 153.2 | C5: =LN(B5/B4) -> 0.023110966 | D5: 5.664 | E5: =LN(D5/D4) -> -0.014373604 | H5: korelacja | I5: =CORREL(C3:C1305,E3:E1305) -> 0.31201895
A6: 44125 | B6: 146.7 | C6: =LN(B6/B5) -> -0.043354572 | D6: 5.496 | E6: =LN(D6/D5) -> -0.030109801
A7: 44126 | B7: 148.5 | C7: =LN(B7/B6) -> 0.012195273 | D7: 5.458 | E7: =LN(D7/D6) -> -0.0069381326
A8: 44127 | B8: 148.3 | C8: =LN(B8/B7) -> -0.0013477091 | D8: 5.272 | E8: =LN(D8/D7) -> -0.034672625 | G8: lp | I8: 1 | J8: 2 | K8: 3 | L8: 4 | M8: 5 | N8: 6 | O8: 7 | P8: 8 | Q8: 9 | R8: 10 | S8: 11
A9: 44130 | B9: 151.2 | C9: =LN(B9/B8) -> 0.019366215 | D9: 5.418 | E9: =LN(D9/D8) -> 0.027316946 | G9: wPGE | I9: 0 | J9: 0.1 | K9: 0.2 | L9: 0.3 | M9: 0.4 | N9: 0.5 | O9: 0.6 | P9: 0.7 | Q9: 0.8 | R9: 0.9 | S9: 1
A10: 44131 | B10: 140 | C10: =LN(B10/B9) -> -0.076961041 | D10: 5.106 | E10: =LN(D10/D9) -> -0.059310425 | G10: wariancja portfela | I10: =I9^2*$J$3+(1-I9)^2*$I$3+2*I9*(1-I9)*$J$4*$I$4*$I$5 -> 0.00077928868 | J10: =J9^2*$J$3+(1-J9)^2*$I$3+2*J9*(1-J9)*$J$4*$I$4*$I$5 -> 0.0006789848 | K10: =K9^2*$J$3+(1-K9)^2*$I$3+2*K9*(1-K9)*$J$4*$I$4*$I$5 -> 0.00059880678 | L10: =L9^2*$J$3+(1-L9)^2*$I$3+2*L9*(1-L9)*$J$4*$I$4*$I$5 -> 0.00053875462 | M10: =M9^2*$J$3+(1-M9)^2*$I$3+2*M9*(1-M9)*$J$4*$I$4*$I$5 -> 0.00049882831 | N10: =N9^2*$J$3+(1-N9)^2*$I$3+2*N9*(1-N9)*$J$4*$I$4*$I$5 -> 0.00047902786 | O10: =O9^2*$J$3+(1-O9)^2*$I$3+2*O9*(1-O9)*$J$4*$I$4*$I$5 -> 0.00047935327 | P10: =P9^2*$J$3+(1-P9)^2*$I$3+2*P9*(1-P9)*$J$4*$I$4*$I$5 -> 0.00049980454 | ... S10: =S9^2*$J$3+(1-S9)^2*$I$3+2*S9*(1-S9)*$J$4*$I$4*$I$5 -> 0.00068191348
A11: 44132 | B11: 126.1 | C11: =LN(B11/B10) -> -0.10456718 | D11: 4.732 | E11: =LN(D11/D10) -> -0.076068373 | G11: ryzyko portfela | I11: =I10^(1/2) -> 0.027915743 | J11: =J10^(1/2) -> 0.026057337 | K11: =K10^(1/2) -> 0.024470529 | L11: =L10^(1/2) -> 0.023211088 | M11: =M10^(1/2) -> 0.022334465 | N11: =N10^(1/2) -> 0.021886705 | O11: =O10^(1/2) -> 0.021894138 | P11: =P10^(1/2) -> 0.022356309 | ... S11: =S10^(1/2) -> 0.026113473
A12: 44133 | B12: 120 | C12: =LN(B12/B11) -> -0.0495835 | D12: 4.496 | E12: =LN(D12/D11) -> -0.051159834 | G12: zwrot portfela | I12: =$J$2*I9+$I$2*(1-I9) -> 0.0013813257 | J12: =$J$2*J9+$I$2*(1-J9) -> 0.0012923646 | K12: =$J$2*K9+$I$2*(1-K9) -> 0.0012034035 | L12: =$J$2*L9+$I$2*(1-L9) -> 0.0011144424 | M12: =$J$2*M9+$I$2*(1-M9) -> 0.0010254813 | N12: =$J$2*N9+$I$2*(1-N9) -> 0.0009365202 | O12: =$J$2*O9+$I$2*(1-O9) -> 0.00084755911 | P12: =$J$2*P9+$I$2*(1-P9) -> 0.00075859802 | ... S12: =$J$2*S9+$I$2*(1-S9) -> 0.00049171475
A13: 44134 | B13: 115.5 | C13: =LN(B13/B12) -> -0.038221213 | D13: 4.51 | E13: =LN(D13/D12) -> 0.0031090409 | G13: wsp. Sharpe'a | I13: =(I12-$N$1)/I11 -> 0.04948196 | J13: =(J12-$N$1)/J11 -> 0.049596955 | K13: =(K12-$N$1)/K11 -> 0.049177665 | L13: =(L12-$N$1)/L11 -> 0.048013362 | M13: =(M12-$N$1)/M11 -> 0.045914747 | N13: =(N12-$N$1)/N11 -> 0.042789456 | O13: =(O12-$N$1)/O11 -> 0.038711692 | P13: =(P12-$N$1)/P11 -> 0.033932168 | ... S13: =(S12-$N$1)/S11 -> 0.018829925
A14: 44137 | B14: 116.6 | C14: =LN(B14/B13) -> 0.009478744 | D14: 4.67 | E14: =LN(D14/D13) -> 0.034861918
A15: 44138 | B15: 132 | C15: =LN(B15/B14) -> 0.12405265 | D15: 5.082 | E15: =LN(D15/D14) -> 0.084545813
A16: 44139 | B16: 125.5 | C16: =LN(B16/B15) -> -0.050496164 | D16: 5.158 | E16: =LN(D16/D15) -> 0.014844023 | J16: wMBK | K16: wPGE
A17: 44140 | B17: 125.1 | C17: =LN(B17/B16) -> -0.0031923411 | D17: 5.244 | E17: =LN(D17/D16) -> 0.016535658 | I17: MVP | J17: =1-K17 -> 0.5 | K17: =N9 -> 0.5 | L17: =MIN(I11:S11) -> 0.021886705
A18: 44141 | B18: 123.7 | C18: =LN(B18/B17) -> -0.011254138 | D18: 5.126 | E18: =LN(D18/D17) -> -0.022758938 | I18: max zwrot | J18: =1-K18 -> 1 | K18: =I9 -> 0 | L18: =MAX(I12:S12) -> 0.0013813257
A19: 44144 | B19: 153.5 | C19: =LN(B19/B18) -> 0.21584129 | D19: 5.906 | E19: =LN(D19/D18) -> 0.14164316 | I19: max Shapre | J19: =1-K19 -> 0.9 | K19: =J9 -> 0.1 | L19: =MAX(I13:S13) -> 0.049596955
A20: 44145 | B20: 169 | C20: =LN(B20/B19) -> 0.096198148 | D20: 5.9 | E20: =LN(D20/D19) -> -0.0010164324
A21: 44146 | B21: 169 | C21: =LN(B21/B20) -> 0 | D21: 5.9 | E21: =LN(D21/D20) -> 0
A22: 44147 | B22: 169.2 | C22: =LN(B22/B21) -> 0.0011827322 | D22: 6.03 | E22: =LN(D22/D21) -> 0.02179466 | G22: OPTYMALIZACJA W SOLVER
A23: 44148 | B23: 160.7 | C23: =LN(B23/B22) -> -0.051542174 | D23: 6.09 | E23: =LN(D23/D22) -> 0.009901071
A24: 44151 | B24: 170.5 | C24: =LN(B24/B23) -> 0.059196024 | D24: 6.05 | E24: =LN(D24/D23) -> -0.0065898097 | G24: Z(w) | H24: =H28^2*J3+I28^2*I3+2*H28*I28*I4*J4*I5 -> 0.0004766722
A25: 44152 | B25: 170 | C25: =LN(B25/B24) -> -0.0029368597 | D25: 5.99 | E25: =LN(D25/D24) -> -0.0099668599 | G25: ryzyko | H25: =SQRT(H24) -> 0.021832824
A26: 44153 | B26: 166.8 | C26: =LN(B26/B25) -> -0.019002947 | D26: 6.094 | E26: =LN(D26/D25) -> 0.017213268
A27: 44154 | B27: 167 | C27: =LN(B27/B26) -> 0.0011983225 | D27: 6.01 | E27: =LN(D27/D26) -> -0.013879932 | G27: wagi | H27: wPGE | I27: wMBK
A28: 44155 | B28: 162.6 | C28: =LN(B28/B27) -> -0.026700615 | D28: 6.066 | E28: =LN(D28/D27) -> 0.0092746607 | H28: 0.54838368 | I28: =1-H28 -> 0.45161632
A29: 44158 | B29: 167.9 | C29: =LN(B29/B28) -> 0.032075367 | D29: 6.128 | E29: =LN(D29/D28) -> 0.010169023
A30: 44159 | B30: 169.6 | C30: =LN(B30/B29) -> 0.010074159 | D30: 6.078 | E30: =LN(D30/D29) -> -0.0081927379 | H30: LHR | I30: znak | J30: RHS
A31: 44160 | B31: 168.8 | C31: =LN(B31/B30) -> -0.0047281412 | D31: 6.1 | E31: =LN(D31/D30) -> 0.0036130767 | G31: suma wag | H31: =H28+I28 -> 1 | I31: = | J31: 1 | K31: =H31=J31 -> TRUE
A32: 44161 | B32: 166.2 | C32: =LN(B32/B31) -> -0.0155227 | D32: 6.1 | E32: =LN(D32/D31) -> 0 | G32: zwrot P | H32: =H28*J2+I28*I2 -> 0.00089347755 | I32: >= | J32: =MIN(I2:J2) -> 0.00049171475
A33: 44162 | B33: 157 | C33: =LN(B33/B32) -> -0.056946077 | D33: 6.1 | E33: =LN(D33/D32) -> 0
A34: 44165 | B34: 151.4 | C34: =LN(B34/B33) -> -0.036320464 | D34: 5.764 | E34: =LN(D34/D33) -> -0.056657093
A35: 44166 | B35: 154 | C35: =LN(B35/B34) -> 0.017027261 | D35: 5.676 | E35: =LN(D35/D34) -> -0.015384919
A36: 44167 | B36: 154.6 | C36: =LN(B36/B35) -> 0.0038885337 | D36: 5.6 | E36: =LN(D36/D35) -> -0.013480162
A37: 44168 | B37: 156.3 | C37: =LN(B37/B36) -> 0.010936101 | D37: 5.502 | E37: =LN(D37/D36) -> -0.017654935
A38: 44169 | B38: 169.5 | C38: =LN(B38/B37) -> 0.081075689 | D38: 5.648 | E38: =LN(D38/D37) -> 0.026189838
A39: 44172 | B39: 175.6 | C39: =LN(B39/B38) -> 0.035355754 | D39: 5.766 | E39: =LN(D39/D38) -> 0.020677099
A40: 44173 | B40: 176 | C40: =LN(B40/B39) -> 0.0022753138 | D40: 5.91 | E40: =LN(D40/D39) -> 0.024667232
...
